Watching for file changes with StatReloader
"GET / HTTP/1.1" 200 9417
"GET /static/images/slide1.jpg HTTP/1.1" 304 0
"GET /static/images/dashboard.png HTTP/1.1" 404 1874
"GET /static/images/chart-preview.png HTTP/1.1" 404 1886
Not Found: /favicon.ico
"GET /favicon.ico HTTP/1.1" 404 3911
"GET /static/images/slide2.jpg HTTP/1.1" 304 0
"GET /static/images/slide3.jpg HTTP/1.1" 304 0
"GET /about/ HTTP/1.1" 200 4611
"GET /contact/ HTTP/1.1" 200 4406
"GET /about/ HTTP/1.1" 200 4611
"GET /contact/ HTTP/1.1" 200 4406
"GET / HTTP/1.1" 200 9417
"GET /static/images/chart-preview.png HTTP/1.1" 404 1886
"GET /static/images/dashboard.png HTTP/1.1" 404 1874
"GET /authentication/login/ HTTP/1.1" 200 2781
"GET /static/images/logo.webp HTTP/1.1" 304 0
"GET /authentication/signup/ HTTP/1.1" 200 4073
"GET /authentication/login/ HTTP/1.1" 200 2781
"POST /authentication/login/ HTTP/1.1" 302 0
"GET /farmer/dashboard/ HTTP/1.1" 200 12210
"GET /authentication/logout/ HTTP/1.1" 302 0
"GET /authentication/login/ HTTP/1.1" 200 2781
"GET /authentication/signup/ HTTP/1.1" 200 4073
"POST /authentication/signup/ HTTP/1.1" 302 0
"GET /authentication/login/ HTTP/1.1" 200 2904
"POST /authentication/login/ HTTP/1.1" 302 0
Internal Server Error: /technician/dashboard/
Traceback (most recent call last):
  File "C:\Users\user\Desktop\soils-sense\.venv\Lib\site-packages\django\db\backends\utils.py", line 105, in _execute
    return self.cursor.execute(sql, params)
           ^^^^^^^^^^^^^^^^^^^^^^^^^^^^^^^^
  File "C:\Users\user\Desktop\soils-sense\.venv\Lib\site-packages\django\db\backends\sqlite3\base.py", line 360, in execute
    return super().execute(query, params)
           ^^^^^^^^^^^^^^^^^^^^^^^^^^^^^^
sqlite3.OperationalError: no such table: farmer_farm

The above exception was the direct cause of the following exception:

Traceback (most recent call last):
  File "C:\Users\user\Desktop\soils-sense\.venv\Lib\site-packages\django\core\handlers\exception.py", line 55, in inner
    response = get_response(request)
               ^^^^^^^^^^^^^^^^^^^^^
  File "C:\Users\user\Desktop\soils-sense\.venv\Lib\site-packages\django\core\handlers\base.py", line 197, in _get_response
    response = wrapped_callback(request, *callback_args, **callback_kwargs)
               ^^^^^^^^^^^^^^^^^^^^^^^^^^^^^^^^^^^^^^^^^^^^^^^^^^^^^^^^^^^^
  File "C:\Users\user\Desktop\soils-sense\apps\technician\views.py", line 24, in dashboard
    farm_count = Farm.objects.count()
                 ^^^^^^^^^^^^^^^^^^^^
  File "C:\Users\user\Desktop\soils-sense\.venv\Lib\site-packages\django\db\models\manager.py", line 87, in manager_method
    return getattr(self.get_queryset(), name)(*args, **kwargs)
           ^^^^^^^^^^^^^^^^^^^^^^^^^^^^^^^^^^^^^^^^^^^^^^^^^^^
  File "C:\Users\user\Desktop\soils-sense\.venv\Lib\site-packages\django\db\models\query.py", line 604, in count
    return self.query.get_count(using=self.db)
           ^^^^^^^^^^^^^^^^^^^^^^^^^^^^^^^^^^^
  File "C:\Users\user\Desktop\soils-sense\.venv\Lib\site-packages\django\db\models\sql\query.py", line 644, in get_count
    return obj.get_aggregation(using, {"__count": Count("*")})["__count"]
           ^^^^^^^^^^^^^^^^^^^^^^^^^^^^^^^^^^^^^^^^^^^^^^^^^^^
  File "C:\Users\user\Desktop\soils-sense\.venv\Lib\site-packages\django\db\models\sql\query.py", line 626, in get_aggregation
    result = compiler.execute_sql(SINGLE)
             ^^^^^^^^^^^^^^^^^^^^^^^^^^^^
  File "C:\Users\user\Desktop\soils-sense\.venv\Lib\site-packages\django\db\models\sql\compiler.py", line 1623, in execute_sql
    cursor.execute(sql, params)
  File "C:\Users\user\Desktop\soils-sense\.venv\Lib\site-packages\django\db\backends\utils.py", line 122, in execute
    return super().execute(sql, params)
           ^^^^^^^^^^^^^^^^^^^^^^^^^^^^
  File "C:\Users\user\Desktop\soils-sense\.venv\Lib\site-packages\django\db\backends\utils.py", line 79, in execute
    return self._execute_with_wrappers(
           ^^^^^^^^^^^^^^^^^^^^^^^^^^^^
  File "C:\Users\user\Desktop\soils-sense\.venv\Lib\site-packages\django\db\backends\utils.py", line 92, in _execute_with_wrappers
    return executor(sql, params, many, context)
           ^^^^^^^^^^^^^^^^^^^^^^^^^^^^^^^^^^^^
  File "C:\Users\user\Desktop\soils-sense\.venv\Lib\site-packages\django\db\backends\utils.py", line 100, in _execute
    with self.db.wrap_database_errors:
  File "C:\Users\user\Desktop\soils-sense\.venv\Lib\site-packages\django\db\utils.py", line 91, in __exit__
    raise dj_exc_value.with_traceback(traceback) from exc_value
  File "C:\Users\user\Desktop\soils-sense\.venv\Lib\site-packages\django\db\backends\utils.py", line 105, in _execute
    return self.cursor.execute(sql, params)
           ^^^^^^^^^^^^^^^^^^^^^^^^^^^^^^^^
  File "C:\Users\user\Desktop\soils-sense\.venv\Lib\site-packages\django\db\backends\sqlite3\base.py", line 360, in execute
    return super().execute(query, params)
           ^^^^^^^^^^^^^^^^^^^^^^^^^^^^^^
django.db.utils.OperationalError: no such table: farmer_farm
"GET /technician/dashboard/ HTTP/1.1" 500 136450
"GET /authentication/reset/ HTTP/1.1" 200 2197
"GET /authentication/reset/ HTTP/1.1" 200 2197
"POST /authentication/reset/ HTTP/1.1" 302 0
"GET /authentication/reset/done/ HTTP/1.1" 200 1289
"GET /authentication/reset/MQ/cspue7-5c6a9a484609e29d21ca80d434a9bd3f/ HTTP/1.1" 302 0
"GET /authentication/reset/MQ/set-password/ HTTP/1.1" 200 2995
"POST /authentication/reset/MQ/set-password/ HTTP/1.1" 302 0
"GET /authentication/reset/complete/ HTTP/1.1" 200 1333
"GET /authentication/login/ HTTP/1.1" 200 2781
"POST /authentication/login/ HTTP/1.1" 302 0
"GET /farmer/dashboard/ HTTP/1.1" 200 12210
"GET /authentication/logout/ HTTP/1.1" 302 0
"GET /authentication/login/ HTTP/1.1" 200 2781
"POST /authentication/login/ HTTP/1.1" 302 0
Internal Server Error: /technician/dashboard/
Traceback (most recent call last):
  File "C:\Users\user\Desktop\soils-sense\.venv\Lib\site-packages\django\db\backends\utils.py", line 105, in _execute
    return self.cursor.execute(sql, params)
           ^^^^^^^^^^^^^^^^^^^^^^^^^^^^^^^^
  File "C:\Users\user\Desktop\soils-sense\.venv\Lib\site-packages\django\db\backends\sqlite3\base.py", line 360, in execute
    return super().execute(query, params)
           ^^^^^^^^^^^^^^^^^^^^^^^^^^^^^^
sqlite3.OperationalError: no such table: farmer_farm

The above exception was the direct cause of the following exception:

Traceback (most recent call last):
  File "C:\Users\user\Desktop\soils-sense\.venv\Lib\site-packages\django\core\handlers\exception.py", line 55, in inner
    response = get_response(request)
               ^^^^^^^^^^^^^^^^^^^^^
  File "C:\Users\user\Desktop\soils-sense\.venv\Lib\site-packages\django\core\handlers\base.py", line 197, in _get_response
    response = wrapped_callback(request, *callback_args, **callback_kwargs)
               ^^^^^^^^^^^^^^^^^^^^^^^^^^^^^^^^^^^^^^^^^^^^^^^^^^^^^^^^^^^^
  File "C:\Users\user\Desktop\soils-sense\apps\technician\views.py", line 24, in dashboard
    farm_count = Farm.objects.count()
                 ^^^^^^^^^^^^^^^^^^^^
  File "C:\Users\user\Desktop\soils-sense\.venv\Lib\site-packages\django\db\models\manager.py", line 87, in manager_method
    return getattr(self.get_queryset(), name)(*args, **kwargs)
           ^^^^^^^^^^^^^^^^^^^^^^^^^^^^^^^^^^^^^^^^^^^^^^^^^^^
  File "C:\Users\user\Desktop\soils-sense\.venv\Lib\site-packages\django\db\models\query.py", line 604, in count
    return self.query.get_count(using=self.db)
           ^^^^^^^^^^^^^^^^^^^^^^^^^^^^^^^^^^^
  File "C:\Users\user\Desktop\soils-sense\.venv\Lib\site-packages\django\db\models\sql\query.py", line 644, in get_count
    return obj.get_aggregation(using, {"__count": Count("*")})["__count"]
           ^^^^^^^^^^^^^^^^^^^^^^^^^^^^^^^^^^^^^^^^^^^^^^^^^^^
  File "C:\Users\user\Desktop\soils-sense\.venv\Lib\site-packages\django\db\models\sql\query.py", line 626, in get_aggregation
    result = compiler.execute_sql(SINGLE)
             ^^^^^^^^^^^^^^^^^^^^^^^^^^^^
  File "C:\Users\user\Desktop\soils-sense\.venv\Lib\site-packages\django\db\models\sql\compiler.py", line 1623, in execute_sql
    cursor.execute(sql, params)
  File "C:\Users\user\Desktop\soils-sense\.venv\Lib\site-packages\django\db\backends\utils.py", line 122, in execute
    return super().execute(sql, params)
           ^^^^^^^^^^^^^^^^^^^^^^^^^^^^
  File "C:\Users\user\Desktop\soils-sense\.venv\Lib\site-packages\django\db\backends\utils.py", line 79, in execute
    return self._execute_with_wrappers(
           ^^^^^^^^^^^^^^^^^^^^^^^^^^^^
  File "C:\Users\user\Desktop\soils-sense\.venv\Lib\site-packages\django\db\backends\utils.py", line 92, in _execute_with_wrappers
    return executor(sql, params, many, context)
           ^^^^^^^^^^^^^^^^^^^^^^^^^^^^^^^^^^^^
  File "C:\Users\user\Desktop\soils-sense\.venv\Lib\site-packages\django\db\backends\utils.py", line 100, in _execute
    with self.db.wrap_database_errors:
  File "C:\Users\user\Desktop\soils-sense\.venv\Lib\site-packages\django\db\utils.py", line 91, in __exit__
    raise dj_exc_value.with_traceback(traceback) from exc_value
  File "C:\Users\user\Desktop\soils-sense\.venv\Lib\site-packages\django\db\backends\utils.py", line 105, in _execute
    return self.cursor.execute(sql, params)
           ^^^^^^^^^^^^^^^^^^^^^^^^^^^^^^^^
  File "C:\Users\user\Desktop\soils-sense\.venv\Lib\site-packages\django\db\backends\sqlite3\base.py", line 360, in execute
    return super().execute(query, params)
           ^^^^^^^^^^^^^^^^^^^^^^^^^^^^^^
django.db.utils.OperationalError: no such table: farmer_farm
"GET /technician/dashboard/ HTTP/1.1" 500 136450
C:\Users\user\Desktop\soils-sense\apps\technician\views.py changed, reloading.
Watching for file changes with StatReloader
C:\Users\user\Desktop\soils-sense\soilsense\settings.py changed, reloading.
