Watching for file changes with StatReloader
"GET / HTTP/1.1" 200 9417
"GET /static/images/slide1.jpg HTTP/1.1" 304 0
"GET /static/images/dashboard.png HTTP/1.1" 404 1874
"GET /static/images/chart-preview.png HTTP/1.1" 404 1886
Not Found: /favicon.ico
"GET /favicon.ico HTTP/1.1" 404 3911
"GET /static/images/slide2.jpg HTTP/1.1" 304 0
"GET /static/images/slide3.jpg HTTP/1.1" 304 0
"GET /about/ HTTP/1.1" 200 4611
"GET /contact/ HTTP/1.1" 200 4406
"GET /about/ HTTP/1.1" 200 4611
"GET /contact/ HTTP/1.1" 200 4406
"GET / HTTP/1.1" 200 9417
"GET /static/images/chart-preview.png HTTP/1.1" 404 1886
"GET /static/images/dashboard.png HTTP/1.1" 404 1874
"GET /authentication/login/ HTTP/1.1" 200 2781
"GET /static/images/logo.webp HTTP/1.1" 304 0
"GET /authentication/signup/ HTTP/1.1" 200 4073
"GET /authentication/login/ HTTP/1.1" 200 2781
"POST /authentication/login/ HTTP/1.1" 302 0
"GET /farmer/dashboard/ HTTP/1.1" 200 12210
"GET /authentication/logout/ HTTP/1.1" 302 0
"GET /authentication/login/ HTTP/1.1" 200 2781
"GET /authentication/signup/ HTTP/1.1" 200 4073
"POST /authentication/signup/ HTTP/1.1" 302 0
"GET /authentication/login/ HTTP/1.1" 200 2904
"POST /authentication/login/ HTTP/1.1" 302 0
Internal Server Error: /technician/dashboard/
Traceback (most recent call last):
  File "C:\Users\user\Desktop\soils-sense\.venv\Lib\site-packages\django\db\backends\utils.py", line 105, in _execute
    return self.cursor.execute(sql, params)
           ^^^^^^^^^^^^^^^^^^^^^^^^^^^^^^^^
  File "C:\Users\user\Desktop\soils-sense\.venv\Lib\site-packages\django\db\backends\sqlite3\base.py", line 360, in execute
    return super().execute(query, params)
           ^^^^^^^^^^^^^^^^^^^^^^^^^^^^^^
sqlite3.OperationalError: no such table: farmer_farm

The above exception was the direct cause of the following exception:

Traceback (most recent call last):
  File "C:\Users\user\Desktop\soils-sense\.venv\Lib\site-packages\django\core\handlers\exception.py", line 55, in inner
    response = get_response(request)
               ^^^^^^^^^^^^^^^^^^^^^
  File "C:\Users\user\Desktop\soils-sense\.venv\Lib\site-packages\django\core\handlers\base.py", line 197, in _get_response
    response = wrapped_callback(request, *callback_args, **callback_kwargs)
               ^^^^^^^^^^^^^^^^^^^^^^^^^^^^^^^^^^^^^^^^^^^^^^^^^^^^^^^^^^^^
  File "C:\Users\user\Desktop\soils-sense\apps\technician\views.py", line 24, in dashboard
    farm_count = Farm.objects.count()
                 ^^^^^^^^^^^^^^^^^^^^
  File "C:\Users\user\Desktop\soils-sense\.venv\Lib\site-packages\django\db\models\manager.py", line 87, in manager_method
    return getattr(self.get_queryset(), name)(*args, **kwargs)
           ^^^^^^^^^^^^^^^^^^^^^^^^^^^^^^^^^^^^^^^^^^^^^^^^^^^
  File "C:\Users\user\Desktop\soils-sense\.venv\Lib\site-packages\django\db\models\query.py", line 604, in count
    return self.query.get_count(using=self.db)
           ^^^^^^^^^^^^^^^^^^^^^^^^^^^^^^^^^^^
  File "C:\Users\user\Desktop\soils-sense\.venv\Lib\site-packages\django\db\models\sql\query.py", line 644, in get_count
    return obj.get_aggregation(using, {"__count": Count("*")})["__count"]
           ^^^^^^^^^^^^^^^^^^^^^^^^^^^^^^^^^^^^^^^^^^^^^^^^^^^
  File "C:\Users\user\Desktop\soils-sense\.venv\Lib\site-packages\django\db\models\sql\query.py", line 626, in get_aggregation
    result = compiler.execute_sql(SINGLE)
             ^^^^^^^^^^^^^^^^^^^^^^^^^^^^
  File "C:\Users\user\Desktop\soils-sense\.venv\Lib\site-packages\django\db\models\sql\compiler.py", line 1623, in execute_sql
    cursor.execute(sql, params)
  File "C:\Users\user\Desktop\soils-sense\.venv\Lib\site-packages\django\db\backends\utils.py", line 122, in execute
    return super().execute(sql, params)
           ^^^^^^^^^^^^^^^^^^^^^^^^^^^^
  File "C:\Users\user\Desktop\soils-sense\.venv\Lib\site-packages\django\db\backends\utils.py", line 79, in execute
    return self._execute_with_wrappers(
           ^^^^^^^^^^^^^^^^^^^^^^^^^^^^
  File "C:\Users\user\Desktop\soils-sense\.venv\Lib\site-packages\django\db\backends\utils.py", line 92, in _execute_with_wrappers
    return executor(sql, params, many, context)
           ^^^^^^^^^^^^^^^^^^^^^^^^^^^^^^^^^^^^
  File "C:\Users\user\Desktop\soils-sense\.venv\Lib\site-packages\django\db\backends\utils.py", line 100, in _execute
    with self.db.wrap_database_errors:
  File "C:\Users\user\Desktop\soils-sense\.venv\Lib\site-packages\django\db\utils.py", line 91, in __exit__
    raise dj_exc_value.with_traceback(traceback) from exc_value
  File "C:\Users\user\Desktop\soils-sense\.venv\Lib\site-packages\django\db\backends\utils.py", line 105, in _execute
    return self.cursor.execute(sql, params)
           ^^^^^^^^^^^^^^^^^^^^^^^^^^^^^^^^
  File "C:\Users\user\Desktop\soils-sense\.venv\Lib\site-packages\django\db\backends\sqlite3\base.py", line 360, in execute
    return super().execute(query, params)
           ^^^^^^^^^^^^^^^^^^^^^^^^^^^^^^
django.db.utils.OperationalError: no such table: farmer_farm
"GET /technician/dashboard/ HTTP/1.1" 500 136450
"GET /authentication/reset/ HTTP/1.1" 200 2197
"GET /authentication/reset/ HTTP/1.1" 200 2197
"POST /authentication/reset/ HTTP/1.1" 302 0
"GET /authentication/reset/done/ HTTP/1.1" 200 1289
"GET /authentication/reset/MQ/cspue7-5c6a9a484609e29d21ca80d434a9bd3f/ HTTP/1.1" 302 0
"GET /authentication/reset/MQ/set-password/ HTTP/1.1" 200 2995
"POST /authentication/reset/MQ/set-password/ HTTP/1.1" 302 0
"GET /authentication/reset/complete/ HTTP/1.1" 200 1333
"GET /authentication/login/ HTTP/1.1" 200 2781
"POST /authentication/login/ HTTP/1.1" 302 0
"GET /farmer/dashboard/ HTTP/1.1" 200 12210
"GET /authentication/logout/ HTTP/1.1" 302 0
"GET /authentication/login/ HTTP/1.1" 200 2781
"POST /authentication/login/ HTTP/1.1" 302 0
Internal Server Error: /technician/dashboard/
Traceback (most recent call last):
  File "C:\Users\user\Desktop\soils-sense\.venv\Lib\site-packages\django\db\backends\utils.py", line 105, in _execute
    return self.cursor.execute(sql, params)
           ^^^^^^^^^^^^^^^^^^^^^^^^^^^^^^^^
  File "C:\Users\user\Desktop\soils-sense\.venv\Lib\site-packages\django\db\backends\sqlite3\base.py", line 360, in execute
    return super().execute(query, params)
           ^^^^^^^^^^^^^^^^^^^^^^^^^^^^^^
sqlite3.OperationalError: no such table: farmer_farm

The above exception was the direct cause of the following exception:

Traceback (most recent call last):
  File "C:\Users\user\Desktop\soils-sense\.venv\Lib\site-packages\django\core\handlers\exception.py", line 55, in inner
    response = get_response(request)
               ^^^^^^^^^^^^^^^^^^^^^
  File "C:\Users\user\Desktop\soils-sense\.venv\Lib\site-packages\django\core\handlers\base.py", line 197, in _get_response
    response = wrapped_callback(request, *callback_args, **callback_kwargs)
               ^^^^^^^^^^^^^^^^^^^^^^^^^^^^^^^^^^^^^^^^^^^^^^^^^^^^^^^^^^^^
  File "C:\Users\user\Desktop\soils-sense\apps\technician\views.py", line 24, in dashboard
    farm_count = Farm.objects.count()
                 ^^^^^^^^^^^^^^^^^^^^
  File "C:\Users\user\Desktop\soils-sense\.venv\Lib\site-packages\django\db\models\manager.py", line 87, in manager_method
    return getattr(self.get_queryset(), name)(*args, **kwargs)
           ^^^^^^^^^^^^^^^^^^^^^^^^^^^^^^^^^^^^^^^^^^^^^^^^^^^
  File "C:\Users\user\Desktop\soils-sense\.venv\Lib\site-packages\django\db\models\query.py", line 604, in count
    return self.query.get_count(using=self.db)
           ^^^^^^^^^^^^^^^^^^^^^^^^^^^^^^^^^^^
  File "C:\Users\user\Desktop\soils-sense\.venv\Lib\site-packages\django\db\models\sql\query.py", line 644, in get_count
    return obj.get_aggregation(using, {"__count": Count("*")})["__count"]
           ^^^^^^^^^^^^^^^^^^^^^^^^^^^^^^^^^^^^^^^^^^^^^^^^^^^
  File "C:\Users\user\Desktop\soils-sense\.venv\Lib\site-packages\django\db\models\sql\query.py", line 626, in get_aggregation
    result = compiler.execute_sql(SINGLE)
             ^^^^^^^^^^^^^^^^^^^^^^^^^^^^
  File "C:\Users\user\Desktop\soils-sense\.venv\Lib\site-packages\django\db\models\sql\compiler.py", line 1623, in execute_sql
    cursor.execute(sql, params)
  File "C:\Users\user\Desktop\soils-sense\.venv\Lib\site-packages\django\db\backends\utils.py", line 122, in execute
    return super().execute(sql, params)
           ^^^^^^^^^^^^^^^^^^^^^^^^^^^^
  File "C:\Users\user\Desktop\soils-sense\.venv\Lib\site-packages\django\db\backends\utils.py", line 79, in execute
    return self._execute_with_wrappers(
           ^^^^^^^^^^^^^^^^^^^^^^^^^^^^
  File "C:\Users\user\Desktop\soils-sense\.venv\Lib\site-packages\django\db\backends\utils.py", line 92, in _execute_with_wrappers
    return executor(sql, params, many, context)
           ^^^^^^^^^^^^^^^^^^^^^^^^^^^^^^^^^^^^
  File "C:\Users\user\Desktop\soils-sense\.venv\Lib\site-packages\django\db\backends\utils.py", line 100, in _execute
    with self.db.wrap_database_errors:
  File "C:\Users\user\Desktop\soils-sense\.venv\Lib\site-packages\django\db\utils.py", line 91, in __exit__
    raise dj_exc_value.with_traceback(traceback) from exc_value
  File "C:\Users\user\Desktop\soils-sense\.venv\Lib\site-packages\django\db\backends\utils.py", line 105, in _execute
    return self.cursor.execute(sql, params)
           ^^^^^^^^^^^^^^^^^^^^^^^^^^^^^^^^
  File "C:\Users\user\Desktop\soils-sense\.venv\Lib\site-packages\django\db\backends\sqlite3\base.py", line 360, in execute
    return super().execute(query, params)
           ^^^^^^^^^^^^^^^^^^^^^^^^^^^^^^
django.db.utils.OperationalError: no such table: farmer_farm
"GET /technician/dashboard/ HTTP/1.1" 500 136450
C:\Users\user\Desktop\soils-sense\apps\technician\views.py changed, reloading.
Watching for file changes with StatReloader
C:\Users\user\Desktop\soils-sense\soilsense\settings.py changed, reloading.
Watching for file changes with StatReloader
Watching for file changes with StatReloader
"GET / HTTP/1.1" 200 9417
"GET /static/images/dashboard.png HTTP/1.1" 404 1874
"GET /static/images/chart-preview.png HTTP/1.1" 404 1886
"GET /authentication/login/ HTTP/1.1" 200 2781
"POST /authentication/login/ HTTP/1.1" 302 0
Internal Server Error: /technician/dashboard/
Traceback (most recent call last):
  File "C:\Users\user\Desktop\soils-sense\.venv\Lib\site-packages\django\db\backends\utils.py", line 105, in _execute
    return self.cursor.execute(sql, params)
           ^^^^^^^^^^^^^^^^^^^^^^^^^^^^^^^^
  File "C:\Users\user\Desktop\soils-sense\.venv\Lib\site-packages\django\db\backends\sqlite3\base.py", line 360, in execute
    return super().execute(query, params)
           ^^^^^^^^^^^^^^^^^^^^^^^^^^^^^^
sqlite3.OperationalError: no such table: farmer_farm

The above exception was the direct cause of the following exception:

Traceback (most recent call last):
  File "C:\Users\user\Desktop\soils-sense\.venv\Lib\site-packages\django\core\handlers\exception.py", line 55, in inner
    response = get_response(request)
               ^^^^^^^^^^^^^^^^^^^^^
  File "C:\Users\user\Desktop\soils-sense\.venv\Lib\site-packages\django\core\handlers\base.py", line 197, in _get_response
    response = wrapped_callback(request, *callback_args, **callback_kwargs)
               ^^^^^^^^^^^^^^^^^^^^^^^^^^^^^^^^^^^^^^^^^^^^^^^^^^^^^^^^^^^^
  File "C:\Users\user\Desktop\soils-sense\apps\technician\views.py", line 24, in dashboard
    farm_count = Farm.objects.count()
                 ^^^^^^^^^^^^^^^^^^^^
  File "C:\Users\user\Desktop\soils-sense\.venv\Lib\site-packages\django\db\models\manager.py", line 87, in manager_method
    return getattr(self.get_queryset(), name)(*args, **kwargs)
           ^^^^^^^^^^^^^^^^^^^^^^^^^^^^^^^^^^^^^^^^^^^^^^^^^^^
  File "C:\Users\user\Desktop\soils-sense\.venv\Lib\site-packages\django\db\models\query.py", line 604, in count
    return self.query.get_count(using=self.db)
           ^^^^^^^^^^^^^^^^^^^^^^^^^^^^^^^^^^^
  File "C:\Users\user\Desktop\soils-sense\.venv\Lib\site-packages\django\db\models\sql\query.py", line 644, in get_count
    return obj.get_aggregation(using, {"__count": Count("*")})["__count"]
           ^^^^^^^^^^^^^^^^^^^^^^^^^^^^^^^^^^^^^^^^^^^^^^^^^^^
  File "C:\Users\user\Desktop\soils-sense\.venv\Lib\site-packages\django\db\models\sql\query.py", line 626, in get_aggregation
    result = compiler.execute_sql(SINGLE)
             ^^^^^^^^^^^^^^^^^^^^^^^^^^^^
  File "C:\Users\user\Desktop\soils-sense\.venv\Lib\site-packages\django\db\models\sql\compiler.py", line 1623, in execute_sql
    cursor.execute(sql, params)
  File "C:\Users\user\Desktop\soils-sense\.venv\Lib\site-packages\django\db\backends\utils.py", line 122, in execute
    return super().execute(sql, params)
           ^^^^^^^^^^^^^^^^^^^^^^^^^^^^
  File "C:\Users\user\Desktop\soils-sense\.venv\Lib\site-packages\django\db\backends\utils.py", line 79, in execute
    return self._execute_with_wrappers(
           ^^^^^^^^^^^^^^^^^^^^^^^^^^^^
  File "C:\Users\user\Desktop\soils-sense\.venv\Lib\site-packages\django\db\backends\utils.py", line 92, in _execute_with_wrappers
    return executor(sql, params, many, context)
           ^^^^^^^^^^^^^^^^^^^^^^^^^^^^^^^^^^^^
  File "C:\Users\user\Desktop\soils-sense\.venv\Lib\site-packages\django\db\backends\utils.py", line 100, in _execute
    with self.db.wrap_database_errors:
  File "C:\Users\user\Desktop\soils-sense\.venv\Lib\site-packages\django\db\utils.py", line 91, in __exit__
    raise dj_exc_value.with_traceback(traceback) from exc_value
  File "C:\Users\user\Desktop\soils-sense\.venv\Lib\site-packages\django\db\backends\utils.py", line 105, in _execute
    return self.cursor.execute(sql, params)
           ^^^^^^^^^^^^^^^^^^^^^^^^^^^^^^^^
  File "C:\Users\user\Desktop\soils-sense\.venv\Lib\site-packages\django\db\backends\sqlite3\base.py", line 360, in execute
    return super().execute(query, params)
           ^^^^^^^^^^^^^^^^^^^^^^^^^^^^^^
django.db.utils.OperationalError: no such table: farmer_farm
"GET /technician/dashboard/ HTTP/1.1" 500 136450
"GET /authentication/reset/MQ/cspue7-5c6a9a484609e29d21ca80d434a9bd3f/ HTTP/1.1" 200 1087
Watching for file changes with StatReloader
"GET / HTTP/1.1" 200 9417
"GET /static/images/dashboard.png HTTP/1.1" 404 1874
"GET /static/images/chart-preview.png HTTP/1.1" 404 1886
"GET /authentication/signup/ HTTP/1.1" 200 4073
"POST /authentication/signup/ HTTP/1.1" 302 0
"GET /authentication/login/ HTTP/1.1" 200 2904
"POST /authentication/login/ HTTP/1.1" 302 0
"GET /farmer/dashboard/ HTTP/1.1" 200 12210
"GET /authentication/logout/ HTTP/1.1" 302 0
"GET /authentication/login/ HTTP/1.1" 200 2781
"GET /authentication/signup/ HTTP/1.1" 200 4073
"POST /authentication/signup/ HTTP/1.1" 302 0
"GET /authentication/login/ HTTP/1.1" 200 2904
"POST /authentication/login/ HTTP/1.1" 302 0
Internal Server Error: /technician/dashboard/
Traceback (most recent call last):
  File "C:\Users\user\Desktop\soils-sense\.venv\Lib\site-packages\django\db\backends\utils.py", line 105, in _execute
    return self.cursor.execute(sql, params)
           ^^^^^^^^^^^^^^^^^^^^^^^^^^^^^^^^
  File "C:\Users\user\Desktop\soils-sense\.venv\Lib\site-packages\django\db\backends\sqlite3\base.py", line 360, in execute
    return super().execute(query, params)
           ^^^^^^^^^^^^^^^^^^^^^^^^^^^^^^
sqlite3.OperationalError: no such table: farmer_farm

The above exception was the direct cause of the following exception:

Traceback (most recent call last):
  File "C:\Users\user\Desktop\soils-sense\.venv\Lib\site-packages\django\core\handlers\exception.py", line 55, in inner
    response = get_response(request)
               ^^^^^^^^^^^^^^^^^^^^^
  File "C:\Users\user\Desktop\soils-sense\.venv\Lib\site-packages\django\core\handlers\base.py", line 197, in _get_response
    response = wrapped_callback(request, *callback_args, **callback_kwargs)
               ^^^^^^^^^^^^^^^^^^^^^^^^^^^^^^^^^^^^^^^^^^^^^^^^^^^^^^^^^^^^
  File "C:\Users\user\Desktop\soils-sense\apps\technician\views.py", line 24, in dashboard
    farm_count = Farm.objects.count()
                 ^^^^^^^^^^^^^^^^^^^^
  File "C:\Users\user\Desktop\soils-sense\.venv\Lib\site-packages\django\db\models\manager.py", line 87, in manager_method
    return getattr(self.get_queryset(), name)(*args, **kwargs)
           ^^^^^^^^^^^^^^^^^^^^^^^^^^^^^^^^^^^^^^^^^^^^^^^^^^^
  File "C:\Users\user\Desktop\soils-sense\.venv\Lib\site-packages\django\db\models\query.py", line 604, in count
    return self.query.get_count(using=self.db)
           ^^^^^^^^^^^^^^^^^^^^^^^^^^^^^^^^^^^
  File "C:\Users\user\Desktop\soils-sense\.venv\Lib\site-packages\django\db\models\sql\query.py", line 644, in get_count
    return obj.get_aggregation(using, {"__count": Count("*")})["__count"]
           ^^^^^^^^^^^^^^^^^^^^^^^^^^^^^^^^^^^^^^^^^^^^^^^^^^^
  File "C:\Users\user\Desktop\soils-sense\.venv\Lib\site-packages\django\db\models\sql\query.py", line 626, in get_aggregation
    result = compiler.execute_sql(SINGLE)
             ^^^^^^^^^^^^^^^^^^^^^^^^^^^^
  File "C:\Users\user\Desktop\soils-sense\.venv\Lib\site-packages\django\db\models\sql\compiler.py", line 1623, in execute_sql
    cursor.execute(sql, params)
  File "C:\Users\user\Desktop\soils-sense\.venv\Lib\site-packages\django\db\backends\utils.py", line 122, in execute
    return super().execute(sql, params)
           ^^^^^^^^^^^^^^^^^^^^^^^^^^^^
  File "C:\Users\user\Desktop\soils-sense\.venv\Lib\site-packages\django\db\backends\utils.py", line 79, in execute
    return self._execute_with_wrappers(
           ^^^^^^^^^^^^^^^^^^^^^^^^^^^^
  File "C:\Users\user\Desktop\soils-sense\.venv\Lib\site-packages\django\db\backends\utils.py", line 92, in _execute_with_wrappers
    return executor(sql, params, many, context)
           ^^^^^^^^^^^^^^^^^^^^^^^^^^^^^^^^^^^^
  File "C:\Users\user\Desktop\soils-sense\.venv\Lib\site-packages\django\db\backends\utils.py", line 100, in _execute
    with self.db.wrap_database_errors:
  File "C:\Users\user\Desktop\soils-sense\.venv\Lib\site-packages\django\db\utils.py", line 91, in __exit__
    raise dj_exc_value.with_traceback(traceback) from exc_value
  File "C:\Users\user\Desktop\soils-sense\.venv\Lib\site-packages\django\db\backends\utils.py", line 105, in _execute
    return self.cursor.execute(sql, params)
           ^^^^^^^^^^^^^^^^^^^^^^^^^^^^^^^^
  File "C:\Users\user\Desktop\soils-sense\.venv\Lib\site-packages\django\db\backends\sqlite3\base.py", line 360, in execute
    return super().execute(query, params)
           ^^^^^^^^^^^^^^^^^^^^^^^^^^^^^^
django.db.utils.OperationalError: no such table: farmer_farm
"GET /technician/dashboard/ HTTP/1.1" 500 136450
"GET /technician/dashboard/ HTTP/1.1" 200 17175
"GET / HTTP/1.1" 200 9417
"GET /contact/ HTTP/1.1" 200 4406
Watching for file changes with StatReloader
Watching for file changes with StatReloader
"GET / HTTP/1.1" 200 9417
"GET /static/images/slide1.jpg HTTP/1.1" 304 0
"GET /static/images/dashboard.png HTTP/1.1" 404 1874
"GET /static/images/chart-preview.png HTTP/1.1" 404 1886
Not Found: /favicon.ico
"GET /favicon.ico HTTP/1.1" 404 3911
"GET /static/images/slide2.jpg HTTP/1.1" 304 0
"GET /authentication/signup/ HTTP/1.1" 200 4073
"GET /static/images/logo.webp HTTP/1.1" 304 0
"GET /authentication/login/ HTTP/1.1" 200 2781
"POST /authentication/login/ HTTP/1.1" 302 0
"GET /farmer/dashboard/ HTTP/1.1" 200 6963
"GET /farmer/profile/ HTTP/1.1" 200 15469
"GET /authentication/reset/ HTTP/1.1" 200 2197
"GET /farmer/analytics/ HTTP/1.1" 200 12664
Internal Server Error: /farmer/soil-data/
Traceback (most recent call last):
  File "C:\Users\user\Desktop\soils-sense\.venv\Lib\site-packages\django\db\backends\utils.py", line 105, in _execute
    return self.cursor.execute(sql, params)
           ^^^^^^^^^^^^^^^^^^^^^^^^^^^^^^^^
  File "C:\Users\user\Desktop\soils-sense\.venv\Lib\site-packages\django\db\backends\sqlite3\base.py", line 360, in execute
    return super().execute(query, params)
           ^^^^^^^^^^^^^^^^^^^^^^^^^^^^^^
sqlite3.OperationalError: no such table: farmer_soilmoisturereading

The above exception was the direct cause of the following exception:

Traceback (most recent call last):
  File "C:\Users\user\Desktop\soils-sense\.venv\Lib\site-packages\django\core\handlers\exception.py", line 55, in inner
    response = get_response(request)
               ^^^^^^^^^^^^^^^^^^^^^
  File "C:\Users\user\Desktop\soils-sense\.venv\Lib\site-packages\django\core\handlers\base.py", line 197, in _get_response
    response = wrapped_callback(request, *callback_args, **callback_kwargs)
               ^^^^^^^^^^^^^^^^^^^^^^^^^^^^^^^^^^^^^^^^^^^^^^^^^^^^^^^^^^^^
  File "C:\Users\user\Desktop\soils-sense\.venv\Lib\site-packages\django\contrib\auth\decorators.py", line 59, in _view_wrapper
    return view_func(request, *args, **kwargs)
           ^^^^^^^^^^^^^^^^^^^^^^^^^^^^^^^^^^^
  File "C:\Users\user\Desktop\soils-sense\apps\farmer\views.py", line 205, in soil_data_management
    return render(request, 'farmer/soil_data_management.html', context)
           ^^^^^^^^^^^^^^^^^^^^^^^^^^^^^^^^^^^^^^^^^^^^^^^^^^^^^^^^^^^^
  File "C:\Users\user\Desktop\soils-sense\.venv\Lib\site-packages\django\shortcuts.py", line 25, in render
    content = loader.render_to_string(template_name, context, request, using=using)
              ^^^^^^^^^^^^^^^^^^^^^^^^^^^^^^^^^^^^^^^^^^^^^^^^^^^^^^^^^^^^^^^^^^^^^
  File "C:\Users\user\Desktop\soils-sense\.venv\Lib\site-packages\django\template\loader.py", line 62, in render_to_string
    return template.render(context, request)
           ^^^^^^^^^^^^^^^^^^^^^^^^^^^^^^^^^
  File "C:\Users\user\Desktop\soils-sense\.venv\Lib\site-packages\django\template\backends\django.py", line 107, in render
    return self.template.render(context)
           ^^^^^^^^^^^^^^^^^^^^^^^^^^^^^
  File "C:\Users\user\Desktop\soils-sense\.venv\Lib\site-packages\django\template\base.py", line 171, in render
    return self._render(context)
           ^^^^^^^^^^^^^^^^^^^^^
  File "C:\Users\user\Desktop\soils-sense\.venv\Lib\site-packages\django\template\base.py", line 163, in _render
    return self.nodelist.render(context)
           ^^^^^^^^^^^^^^^^^^^^^^^^^^^^^
  File "C:\Users\user\Desktop\soils-sense\.venv\Lib\site-packages\django\template\base.py", line 1016, in render
    return SafeString("".join([node.render_annotated(context) for node in self]))
                               ^^^^^^^^^^^^^^^^^^^^^^^^^^^^^^
  File "C:\Users\user\Desktop\soils-sense\.venv\Lib\site-packages\django\template\base.py", line 977, in render_annotated
    return self.render(context)
           ^^^^^^^^^^^^^^^^^^^^
  File "C:\Users\user\Desktop\soils-sense\.venv\Lib\site-packages\django\template\loader_tags.py", line 159, in render
    return compiled_parent._render(context)
           ^^^^^^^^^^^^^^^^^^^^^^^^^^^^^^^^
  File "C:\Users\user\Desktop\soils-sense\.venv\Lib\site-packages\django\template\base.py", line 163, in _render
    return self.nodelist.render(context)
           ^^^^^^^^^^^^^^^^^^^^^^^^^^^^^
  File "C:\Users\user\Desktop\soils-sense\.venv\Lib\site-packages\django\template\base.py", line 1016, in render
    return SafeString("".join([node.render_annotated(context) for node in self]))
                               ^^^^^^^^^^^^^^^^^^^^^^^^^^^^^^
  File "C:\Users\user\Desktop\soils-sense\.venv\Lib\site-packages\django\template\base.py", line 977, in render_annotated
    return self.render(context)
           ^^^^^^^^^^^^^^^^^^^^
  File "C:\Users\user\Desktop\soils-sense\.venv\Lib\site-packages\django\template\loader_tags.py", line 65, in render
    result = block.nodelist.render(context)
             ^^^^^^^^^^^^^^^^^^^^^^^^^^^^^^
  File "C:\Users\user\Desktop\soils-sense\.venv\Lib\site-packages\django\template\base.py", line 1016, in render
    return SafeString("".join([node.render_annotated(context) for node in self]))
                               ^^^^^^^^^^^^^^^^^^^^^^^^^^^^^^
  File "C:\Users\user\Desktop\soils-sense\.venv\Lib\site-packages\django\template\base.py", line 977, in render_annotated
    return self.render(context)
           ^^^^^^^^^^^^^^^^^^^^
  File "C:\Users\user\Desktop\soils-sense\.venv\Lib\site-packages\django\template\defaulttags.py", line 199, in render
    len_values = len(values)
                 ^^^^^^^^^^^
  File "C:\Users\user\Desktop\soils-sense\.venv\Lib\site-packages\django\db\models\query.py", line 366, in __len__
    self._fetch_all()
  File "C:\Users\user\Desktop\soils-sense\.venv\Lib\site-packages\django\db\models\query.py", line 1949, in _fetch_all
    self._result_cache = list(self._iterable_class(self))
                         ^^^^^^^^^^^^^^^^^^^^^^^^^^^^^^^^
  File "C:\Users\user\Desktop\soils-sense\.venv\Lib\site-packages\django\db\models\query.py", line 91, in __iter__
    results = compiler.execute_sql(
              ^^^^^^^^^^^^^^^^^^^^^
  File "C:\Users\user\Desktop\soils-sense\.venv\Lib\site-packages\django\db\models\sql\compiler.py", line 1623, in execute_sql
    cursor.execute(sql, params)
  File "C:\Users\user\Desktop\soils-sense\.venv\Lib\site-packages\django\db\backends\utils.py", line 122, in execute
    return super().execute(sql, params)
           ^^^^^^^^^^^^^^^^^^^^^^^^^^^^
  File "C:\Users\user\Desktop\soils-sense\.venv\Lib\site-packages\django\db\backends\utils.py", line 79, in execute
    return self._execute_with_wrappers(
           ^^^^^^^^^^^^^^^^^^^^^^^^^^^^
  File "C:\Users\user\Desktop\soils-sense\.venv\Lib\site-packages\django\db\backends\utils.py", line 92, in _execute_with_wrappers
    return executor(sql, params, many, context)
           ^^^^^^^^^^^^^^^^^^^^^^^^^^^^^^^^^^^^
  File "C:\Users\user\Desktop\soils-sense\.venv\Lib\site-packages\django\db\backends\utils.py", line 100, in _execute
    with self.db.wrap_database_errors:
  File "C:\Users\user\Desktop\soils-sense\.venv\Lib\site-packages\django\db\utils.py", line 91, in __exit__
    raise dj_exc_value.with_traceback(traceback) from exc_value
  File "C:\Users\user\Desktop\soils-sense\.venv\Lib\site-packages\django\db\backends\utils.py", line 105, in _execute
    return self.cursor.execute(sql, params)
           ^^^^^^^^^^^^^^^^^^^^^^^^^^^^^^^^
  File "C:\Users\user\Desktop\soils-sense\.venv\Lib\site-packages\django\db\backends\sqlite3\base.py", line 360, in execute
    return super().execute(query, params)
           ^^^^^^^^^^^^^^^^^^^^^^^^^^^^^^
django.db.utils.OperationalError: no such table: farmer_soilmoisturereading
"GET /farmer/soil-data/ HTTP/1.1" 500 227266
"GET /farmer/dashboard/ HTTP/1.1" 200 6963
"GET /farmer/recommendations/ HTTP/1.1" 200 15736
"GET /authentication/logout/ HTTP/1.1" 302 0
"GET /landing_page/ HTTP/1.1" 200 9417
"GET /static/images/dashboard.png HTTP/1.1" 404 1874
"GET /static/images/chart-preview.png HTTP/1.1" 404 1886
"GET /authentication/login/ HTTP/1.1" 200 2781
"POST /authentication/login/ HTTP/1.1" 302 0
Internal Server Error: /technician/dashboard/
Traceback (most recent call last):
  File "C:\Users\user\Desktop\soils-sense\.venv\Lib\site-packages\django\db\backends\utils.py", line 105, in _execute
    return self.cursor.execute(sql, params)
           ^^^^^^^^^^^^^^^^^^^^^^^^^^^^^^^^
  File "C:\Users\user\Desktop\soils-sense\.venv\Lib\site-packages\django\db\backends\sqlite3\base.py", line 360, in execute
    return super().execute(query, params)
           ^^^^^^^^^^^^^^^^^^^^^^^^^^^^^^
sqlite3.OperationalError: no such table: farmer_soilmoisturereading

The above exception was the direct cause of the following exception:

Traceback (most recent call last):
  File "C:\Users\user\Desktop\soils-sense\.venv\Lib\site-packages\django\core\handlers\exception.py", line 55, in inner
    response = get_response(request)
               ^^^^^^^^^^^^^^^^^^^^^
  File "C:\Users\user\Desktop\soils-sense\.venv\Lib\site-packages\django\core\handlers\base.py", line 197, in _get_response
    response = wrapped_callback(request, *callback_args, **callback_kwargs)
               ^^^^^^^^^^^^^^^^^^^^^^^^^^^^^^^^^^^^^^^^^^^^^^^^^^^^^^^^^^^^
  File "C:\Users\user\Desktop\soils-sense\apps\technician\views.py", line 38, in dashboard
    total_readings = SoilMoistureReading.objects.count()
                     ^^^^^^^^^^^^^^^^^^^^^^^^^^^^^^^^^^^
  File "C:\Users\user\Desktop\soils-sense\.venv\Lib\site-packages\django\db\models\manager.py", line 87, in manager_method
    return getattr(self.get_queryset(), name)(*args, **kwargs)
           ^^^^^^^^^^^^^^^^^^^^^^^^^^^^^^^^^^^^^^^^^^^^^^^^^^^
  File "C:\Users\user\Desktop\soils-sense\.venv\Lib\site-packages\django\db\models\query.py", line 604, in count
    return self.query.get_count(using=self.db)
           ^^^^^^^^^^^^^^^^^^^^^^^^^^^^^^^^^^^
  File "C:\Users\user\Desktop\soils-sense\.venv\Lib\site-packages\django\db\models\sql\query.py", line 644, in get_count
    return obj.get_aggregation(using, {"__count": Count("*")})["__count"]
           ^^^^^^^^^^^^^^^^^^^^^^^^^^^^^^^^^^^^^^^^^^^^^^^^^^^
  File "C:\Users\user\Desktop\soils-sense\.venv\Lib\site-packages\django\db\models\sql\query.py", line 626, in get_aggregation
    result = compiler.execute_sql(SINGLE)
             ^^^^^^^^^^^^^^^^^^^^^^^^^^^^
  File "C:\Users\user\Desktop\soils-sense\.venv\Lib\site-packages\django\db\models\sql\compiler.py", line 1623, in execute_sql
    cursor.execute(sql, params)
  File "C:\Users\user\Desktop\soils-sense\.venv\Lib\site-packages\django\db\backends\utils.py", line 122, in execute
    return super().execute(sql, params)
           ^^^^^^^^^^^^^^^^^^^^^^^^^^^^
  File "C:\Users\user\Desktop\soils-sense\.venv\Lib\site-packages\django\db\backends\utils.py", line 79, in execute
    return self._execute_with_wrappers(
           ^^^^^^^^^^^^^^^^^^^^^^^^^^^^
  File "C:\Users\user\Desktop\soils-sense\.venv\Lib\site-packages\django\db\backends\utils.py", line 92, in _execute_with_wrappers
    return executor(sql, params, many, context)
           ^^^^^^^^^^^^^^^^^^^^^^^^^^^^^^^^^^^^
  File "C:\Users\user\Desktop\soils-sense\.venv\Lib\site-packages\django\db\backends\utils.py", line 100, in _execute
    with self.db.wrap_database_errors:
  File "C:\Users\user\Desktop\soils-sense\.venv\Lib\site-packages\django\db\utils.py", line 91, in __exit__
    raise dj_exc_value.with_traceback(traceback) from exc_value
  File "C:\Users\user\Desktop\soils-sense\.venv\Lib\site-packages\django\db\backends\utils.py", line 105, in _execute
    return self.cursor.execute(sql, params)
           ^^^^^^^^^^^^^^^^^^^^^^^^^^^^^^^^
  File "C:\Users\user\Desktop\soils-sense\.venv\Lib\site-packages\django\db\backends\sqlite3\base.py", line 360, in execute
    return super().execute(query, params)
           ^^^^^^^^^^^^^^^^^^^^^^^^^^^^^^
django.db.utils.OperationalError: no such table: farmer_soilmoisturereading
"GET /technician/dashboard/ HTTP/1.1" 500 139037
Watching for file changes with StatReloader
"GET /technician/dashboard/ HTTP/1.1" 200 22979
"GET /technician/soil-readings/ HTTP/1.1" 200 11572
"GET /technician/analytics/ HTTP/1.1" 200 16581
"GET /technician/farm-locations/ HTTP/1.1" 200 15142
"GET /technician/dashboard/ HTTP/1.1" 200 22979
"GET /technician/soil-readings/ HTTP/1.1" 200 11572
"GET /technician/sensor-config/ HTTP/1.1" 200 16623
"GET /technician/analytics/ HTTP/1.1" 200 16581
"GET /technician/reports/ HTTP/1.1" 200 13306
"GET /technician/profile/ HTTP/1.1" 200 19121
C:\Users\user\Desktop\soils-sense\apps\administrator\views.py changed, reloading.
Watching for file changes with StatReloader
Watching for file changes with StatReloader
"GET /technician/profile/ HTTP/1.1" 200 19121
Watching for file changes with StatReloader
"GET / HTTP/1.1" 200 9417
"GET /static/images/dashboard.png HTTP/1.1" 404 1874
"GET /static/images/chart-preview.png HTTP/1.1" 404 1886
"GET /authentication/login/ HTTP/1.1" 200 2781
"POST /authentication/login/ HTTP/1.1" 302 0
"GET /technician/dashboard/ HTTP/1.1" 200 22979
"GET /technician/profile/ HTTP/1.1" 200 19121
"GET /technician/farm-locations/ HTTP/1.1" 200 15142
"GET /technician/dashboard/ HTTP/1.1" 200 22979
Not Found: /administration/dashboard/
"GET /administration/dashboard/ HTTP/1.1" 404 3953
"GET /admin/ HTTP/1.1" 302 0
"GET /admin/login/?next=/admin/ HTTP/1.1" 200 3398
"GET /static/jazzmin/css/main.css HTTP/1.1" 200 16969
"GET /static/vendor/adminlte/img/AdminLTELogo.png HTTP/1.1" 200 2637
"GET /static/vendor/fontawesome-free/css/all.min.css HTTP/1.1" 200 103009
"GET /static/vendor/adminlte/css/adminlte.min.css HTTP/1.1" 200 1382975
"GET /static/vendor/adminlte/js/adminlte.min.js HTTP/1.1" 200 44244
"GET /static/vendor/bootstrap/js/bootstrap.min.js HTTP/1.1" 200 62440
"GET /static/vendor/fontawesome-free/webfonts/fa-solid-900.woff2 HTTP/1.1" 200 156400
"GET /static/admin/js/vendor/jquery/jquery.js HTTP/1.1" 200 285314
Watching for file changes with StatReloader
"GET /authentication/signup/ HTTP/1.1" 200 4989
"GET / HTTP/1.1" 200 9417
"GET /static/images/dashboard.png HTTP/1.1" 404 1874
"GET /static/images/chart-preview.png HTTP/1.1" 404 1886
"GET /static/images/slide3.jpg HTTP/1.1" 304 0
"GET /authentication/login/ HTTP/1.1" 200 3602
"GET / HTTP/1.1" 200 9417
"GET /static/images/dashboard.png HTTP/1.1" 404 1874
"GET /static/images/chart-preview.png HTTP/1.1" 404 1886
"GET /authentication/login/ HTTP/1.1" 200 3602
"GET /authentication/signup/ HTTP/1.1" 200 4894
"GET / HTTP/1.1" 200 9417
"GET /static/images/dashboard.png HTTP/1.1" 404 1874
"GET /static/images/chart-preview.png HTTP/1.1" 404 1886
"GET /authentication/login/ HTTP/1.1" 200 3602
C:\Users\user\Desktop\soils-sense\apps\landing_page\models.py changed, reloading.
Watching for file changes with StatReloader
C:\Users\user\Desktop\soils-sense\soilsense\settings.py changed, reloading.
Watching for file changes with StatReloader
C:\Users\user\Desktop\soils-sense\apps\administrator\views.py changed, reloading.
Watching for file changes with StatReloader
Watching for file changes with StatReloader
"GET / HTTP/1.1" 200 9417
"GET /static/images/dashboard.png HTTP/1.1" 404 1874
"GET /static/images/chart-preview.png HTTP/1.1" 404 1886
"GET /authentication/login/ HTTP/1.1" 200 2781
"POST /authentication/login/ HTTP/1.1" 302 0
"GET /technician/dashboard/ HTTP/1.1" 200 22979
"GET /technician/farm-locations/ HTTP/1.1" 200 15142
"GET /technician/analytics/ HTTP/1.1" 200 16581
"GET /technician/farm-locations/ HTTP/1.1" 200 15142
"GET /technician/sensor-config/ HTTP/1.1" 200 16623
"GET /technician/analytics/ HTTP/1.1" 200 16581
"GET /technician/reports/ HTTP/1.1" 200 13306
"GET /technician/profile/ HTTP/1.1" 200 19121
"GET /technician/dashboard/ HTTP/1.1" 200 22979
"GET /technician/sensor-config/ HTTP/1.1" 200 16623
C:\Users\user\Desktop\soils-sense\authentication\views.py changed, reloading.
Watching for file changes with StatReloader
C:\Users\user\Desktop\soils-sense\soilsense\settings.py changed, reloading.
Watching for file changes with StatReloader
Watching for file changes with StatReloader
"GET / HTTP/1.1" 200 7339
"GET /static/images/dashboard.png HTTP/1.1" 404 1874
"GET /static/images/chart-preview.png HTTP/1.1" 404 1886
C:\Users\user\Desktop\soils-sense\apps\farmer\urls.py changed, reloading.
Watching for file changes with StatReloader
Watching for file changes with StatReloader
"GET / HTTP/1.1" 200 9417
"GET /static/images/dashboard.png HTTP/1.1" 404 1874
"GET /static/images/chart-preview.png HTTP/1.1" 404 1886
"GET /authentication/login/ HTTP/1.1" 200 2781
"GET /authentication/signup/ HTTP/1.1" 200 4073
"GET /authentication/login/ HTTP/1.1" 200 2781
"GET /authentication/signup/ HTTP/1.1" 200 4073
"GET /contact/ HTTP/1.1" 200 4408
"GET /authentication/login/ HTTP/1.1" 200 2781
"POST /authentication/login/ HTTP/1.1" 302 0
"GET /technician/dashboard/ HTTP/1.1" 200 22979
"GET /technician/dashboard/ HTTP/1.1" 200 22979
"GET /technician/reports/ HTTP/1.1" 200 13306
"GET /technician/dashboard/ HTTP/1.1" 200 22979
"GET /technician/dashboard/ HTTP/1.1" 200 22979
"GET /technician/profile/ HTTP/1.1" 200 19121
"GET /authentication/reset/ HTTP/1.1" 200 2197
"GET /technician/profile/ HTTP/1.1" 200 19121
"GET /authentication/reset/ HTTP/1.1" 200 3224
"GET / HTTP/1.1" 200 9417
"GET /static/images/dashboard.png HTTP/1.1" 404 1874
"GET /static/images/chart-preview.png HTTP/1.1" 404 1886
"GET /authentication/login/ HTTP/1.1" 200 3808
"GET /authentication/login/ HTTP/1.1" 200 4101
"GET /static/landing_page/images/slide1.jpg HTTP/1.1" 404 1904
"GET /authentication/signup/ HTTP/1.1" 200 5393
"GET /static/landing_page/images/slide1.jpg HTTP/1.1" 404 1904
"GET /authentication/signup/ HTTP/1.1" 200 5130
"GET /authentication/login/ HTTP/1.1" 200 3838
"GET /authentication/reset/ HTTP/1.1" 200 3254
"POST /authentication/reset/ HTTP/1.1" 302 0
"GET /authentication/reset/done/ HTTP/1.1" 200 2346
"GET /authentication/reset/MQ/csrws4-313776a3da19c873485ca1dc2811ab0c/ HTTP/1.1" 302 0
"GET /authentication/reset/MQ/set-password/ HTTP/1.1" 200 4052
"GET / HTTP/1.1" 200 9417
"GET /static/images/dashboard.png HTTP/1.1" 404 1874
"GET /static/images/chart-preview.png HTTP/1.1" 404 1886
"GET /authentication/login/ HTTP/1.1" 200 3838
"GET /authentication/signup/ HTTP/1.1" 200 5130
C:\Users\user\Desktop\soils-sense\apps\administrator\views.py changed, reloading.
Watching for file changes with StatReloader
C:\Users\user\Desktop\soils-sense\soilsense\settings.py changed, reloading.
Watching for file changes with StatReloader
Watching for file changes with StatReloader
"GET / HTTP/1.1" 200 7339
"GET /static/images/dashboard.png HTTP/1.1" 404 1874
"GET /static/images/chart-preview.png HTTP/1.1" 404 1886
"GET /authentication/signup/ HTTP/1.1" 200 4894
"GET /authentication/login/ HTTP/1.1" 200 3602
"GET / HTTP/1.1" 200 7339
"GET /static/images/dashboard.png HTTP/1.1" 404 1874
"GET /static/images/chart-preview.png HTTP/1.1" 404 1886
Internal Server Error: /admin/
Traceback (most recent call last):
  File "C:\Users\user\Desktop\soils-sense\.venv\Lib\site-packages\django\db\backends\utils.py", line 105, in _execute
    return self.cursor.execute(sql, params)
           ^^^^^^^^^^^^^^^^^^^^^^^^^^^^^^^^
  File "C:\Users\user\Desktop\soils-sense\.venv\Lib\site-packages\django\db\backends\sqlite3\base.py", line 360, in execute
    return super().execute(query, params)
           ^^^^^^^^^^^^^^^^^^^^^^^^^^^^^^
sqlite3.OperationalError: no such column: authentication_user.reset_code

The above exception was the direct cause of the following exception:

Traceback (most recent call last):
  File "C:\Users\user\Desktop\soils-sense\.venv\Lib\site-packages\django\core\handlers\exception.py", line 55, in inner
    response = get_response(request)
               ^^^^^^^^^^^^^^^^^^^^^
  File "C:\Users\user\Desktop\soils-sense\.venv\Lib\site-packages\django\core\handlers\base.py", line 197, in _get_response
    response = wrapped_callback(request, *callback_args, **callback_kwargs)
               ^^^^^^^^^^^^^^^^^^^^^^^^^^^^^^^^^^^^^^^^^^^^^^^^^^^^^^^^^^^^
  File "C:\Users\user\Desktop\soils-sense\.venv\Lib\site-packages\django\contrib\admin\sites.py", line 265, in wrapper
    return self.admin_view(view, cacheable)(*args, **kwargs)
           ^^^^^^^^^^^^^^^^^^^^^^^^^^^^^^^^^^^^^^^^^^^^^^^^^
  File "C:\Users\user\Desktop\soils-sense\.venv\Lib\site-packages\django\utils\decorators.py", line 192, in _view_wrapper
    result = _process_exception(request, e)
             ^^^^^^^^^^^^^^^^^^^^^^^^^^^^^^
  File "C:\Users\user\Desktop\soils-sense\.venv\Lib\site-packages\django\utils\decorators.py", line 190, in _view_wrapper
    response = view_func(request, *args, **kwargs)
               ^^^^^^^^^^^^^^^^^^^^^^^^^^^^^^^^^^^
  File "C:\Users\user\Desktop\soils-sense\.venv\Lib\site-packages\django\views\decorators\cache.py", line 80, in _view_wrapper
    response = view_func(request, *args, **kwargs)
               ^^^^^^^^^^^^^^^^^^^^^^^^^^^^^^^^^^^
  File "C:\Users\user\Desktop\soils-sense\.venv\Lib\site-packages\django\contrib\admin\sites.py", line 234, in inner
    if not self.has_permission(request):
           ^^^^^^^^^^^^^^^^^^^^^^^^^^^^
  File "C:\Users\user\Desktop\soils-sense\.venv\Lib\site-packages\django\contrib\admin\sites.py", line 207, in has_permission
    return request.user.is_active and request.user.is_staff
           ^^^^^^^^^^^^^^^^^^^^^^
  File "C:\Users\user\Desktop\soils-sense\.venv\Lib\site-packages\django\utils\functional.py", line 251, in inner
    self._setup()
  File "C:\Users\user\Desktop\soils-sense\.venv\Lib\site-packages\django\utils\functional.py", line 404, in _setup
    self._wrapped = self._setupfunc()
                    ^^^^^^^^^^^^^^^^^
  File "C:\Users\user\Desktop\soils-sense\.venv\Lib\site-packages\django\contrib\auth\middleware.py", line 40, in <lambda>
    request.user = SimpleLazyObject(lambda: get_user(request))
                                            ^^^^^^^^^^^^^^^^^
  File "C:\Users\user\Desktop\soils-sense\.venv\Lib\site-packages\django\contrib\auth\middleware.py", line 20, in get_user
    request._cached_user = auth.get_user(request)
                           ^^^^^^^^^^^^^^^^^^^^^^
  File "C:\Users\user\Desktop\soils-sense\.venv\Lib\site-packages\django\contrib\auth\__init__.py", line 311, in get_user
    user = backend.get_user(user_id)
           ^^^^^^^^^^^^^^^^^^^^^^^^^
  File "C:\Users\user\Desktop\soils-sense\.venv\Lib\site-packages\django\contrib\auth\backends.py", line 232, in get_user
    user = UserModel._default_manager.get(pk=user_id)
           ^^^^^^^^^^^^^^^^^^^^^^^^^^^^^^^^^^^^^^^^^^
  File "C:\Users\user\Desktop\soils-sense\.venv\Lib\site-packages\django\db\models\manager.py", line 87, in manager_method
    return getattr(self.get_queryset(), name)(*args, **kwargs)
           ^^^^^^^^^^^^^^^^^^^^^^^^^^^^^^^^^^^^^^^^^^^^^^^^^^^
  File "C:\Users\user\Desktop\soils-sense\.venv\Lib\site-packages\django\db\models\query.py", line 629, in get
    num = len(clone)
          ^^^^^^^^^^
  File "C:\Users\user\Desktop\soils-sense\.venv\Lib\site-packages\django\db\models\query.py", line 366, in __len__
    self._fetch_all()
  File "C:\Users\user\Desktop\soils-sense\.venv\Lib\site-packages\django\db\models\query.py", line 1949, in _fetch_all
    self._result_cache = list(self._iterable_class(self))
                         ^^^^^^^^^^^^^^^^^^^^^^^^^^^^^^^^
  File "C:\Users\user\Desktop\soils-sense\.venv\Lib\site-packages\django\db\models\query.py", line 91, in __iter__
    results = compiler.execute_sql(
              ^^^^^^^^^^^^^^^^^^^^^
  File "C:\Users\user\Desktop\soils-sense\.venv\Lib\site-packages\django\db\models\sql\compiler.py", line 1623, in execute_sql
    cursor.execute(sql, params)
  File "C:\Users\user\Desktop\soils-sense\.venv\Lib\site-packages\django\db\backends\utils.py", line 122, in execute
    return super().execute(sql, params)
           ^^^^^^^^^^^^^^^^^^^^^^^^^^^^
  File "C:\Users\user\Desktop\soils-sense\.venv\Lib\site-packages\django\db\backends\utils.py", line 79, in execute
    return self._execute_with_wrappers(
           ^^^^^^^^^^^^^^^^^^^^^^^^^^^^
  File "C:\Users\user\Desktop\soils-sense\.venv\Lib\site-packages\django\db\backends\utils.py", line 92, in _execute_with_wrappers
    return executor(sql, params, many, context)
           ^^^^^^^^^^^^^^^^^^^^^^^^^^^^^^^^^^^^
  File "C:\Users\user\Desktop\soils-sense\.venv\Lib\site-packages\django\db\backends\utils.py", line 100, in _execute
    with self.db.wrap_database_errors:
  File "C:\Users\user\Desktop\soils-sense\.venv\Lib\site-packages\django\db\utils.py", line 91, in __exit__
    raise dj_exc_value.with_traceback(traceback) from exc_value
  File "C:\Users\user\Desktop\soils-sense\.venv\Lib\site-packages\django\db\backends\utils.py", line 105, in _execute
    return self.cursor.execute(sql, params)
           ^^^^^^^^^^^^^^^^^^^^^^^^^^^^^^^^
  File "C:\Users\user\Desktop\soils-sense\.venv\Lib\site-packages\django\db\backends\sqlite3\base.py", line 360, in execute
    return super().execute(query, params)
           ^^^^^^^^^^^^^^^^^^^^^^^^^^^^^^
django.db.utils.OperationalError: no such column: authentication_user.reset_code
"GET /admin/ HTTP/1.1" 500 197083
"GET /administrator/ HTTP/1.1" 200 6332
"GET /administrator/users/ HTTP/1.1" 200 6430
"GET /administrator/ml-models/ HTTP/1.1" 200 6246
"GET /administrator/data/ HTTP/1.1" 200 6436
"GET /administrator/reports/ HTTP/1.1" 200 6243
"GET /administrator/notifications/ HTTP/1.1" 200 6490
"GET /administrator/sensors/ HTTP/1.1" 200 6449
Internal Server Error: /authentication/logout/
Traceback (most recent call last):
  File "C:\Users\user\Desktop\soils-sense\.venv\Lib\site-packages\django\db\backends\utils.py", line 105, in _execute
    return self.cursor.execute(sql, params)
           ^^^^^^^^^^^^^^^^^^^^^^^^^^^^^^^^
  File "C:\Users\user\Desktop\soils-sense\.venv\Lib\site-packages\django\db\backends\sqlite3\base.py", line 360, in execute
    return super().execute(query, params)
           ^^^^^^^^^^^^^^^^^^^^^^^^^^^^^^
sqlite3.OperationalError: no such column: authentication_user.reset_code

The above exception was the direct cause of the following exception:

Traceback (most recent call last):
  File "C:\Users\user\Desktop\soils-sense\.venv\Lib\site-packages\django\core\handlers\exception.py", line 55, in inner
    response = get_response(request)
               ^^^^^^^^^^^^^^^^^^^^^
  File "C:\Users\user\Desktop\soils-sense\.venv\Lib\site-packages\django\core\handlers\base.py", line 197, in _get_response
    response = wrapped_callback(request, *callback_args, **callback_kwargs)
               ^^^^^^^^^^^^^^^^^^^^^^^^^^^^^^^^^^^^^^^^^^^^^^^^^^^^^^^^^^^^
  File "C:\Users\user\Desktop\soils-sense\.venv\Lib\site-packages\django\views\generic\base.py", line 105, in view
    return self.dispatch(request, *args, **kwargs)
           ^^^^^^^^^^^^^^^^^^^^^^^^^^^^^^^^^^^^^^^
  File "C:\Users\user\Desktop\soils-sense\.venv\Lib\site-packages\django\views\generic\base.py", line 144, in dispatch
    return handler(request, *args, **kwargs)
           ^^^^^^^^^^^^^^^^^^^^^^^^^^^^^^^^^
  File "C:\Users\user\Desktop\soils-sense\authentication\views.py", line 60, in get
    logout(request)
  File "C:\Users\user\Desktop\soils-sense\.venv\Lib\site-packages\django\contrib\auth\__init__.py", line 251, in logout
    if not getattr(user, "is_authenticated", True):
           ^^^^^^^^^^^^^^^^^^^^^^^^^^^^^^^^^^^^^^^
  File "C:\Users\user\Desktop\soils-sense\.venv\Lib\site-packages\django\utils\functional.py", line 251, in inner
    self._setup()
  File "C:\Users\user\Desktop\soils-sense\.venv\Lib\site-packages\django\utils\functional.py", line 404, in _setup
    self._wrapped = self._setupfunc()
                    ^^^^^^^^^^^^^^^^^
  File "C:\Users\user\Desktop\soils-sense\.venv\Lib\site-packages\django\contrib\auth\middleware.py", line 40, in <lambda>
    request.user = SimpleLazyObject(lambda: get_user(request))
                                            ^^^^^^^^^^^^^^^^^
  File "C:\Users\user\Desktop\soils-sense\.venv\Lib\site-packages\django\contrib\auth\middleware.py", line 20, in get_user
    request._cached_user = auth.get_user(request)
                           ^^^^^^^^^^^^^^^^^^^^^^
  File "C:\Users\user\Desktop\soils-sense\.venv\Lib\site-packages\django\contrib\auth\__init__.py", line 311, in get_user
    user = backend.get_user(user_id)
           ^^^^^^^^^^^^^^^^^^^^^^^^^
  File "C:\Users\user\Desktop\soils-sense\.venv\Lib\site-packages\django\contrib\auth\backends.py", line 232, in get_user
    user = UserModel._default_manager.get(pk=user_id)
           ^^^^^^^^^^^^^^^^^^^^^^^^^^^^^^^^^^^^^^^^^^
  File "C:\Users\user\Desktop\soils-sense\.venv\Lib\site-packages\django\db\models\manager.py", line 87, in manager_method
    return getattr(self.get_queryset(), name)(*args, **kwargs)
           ^^^^^^^^^^^^^^^^^^^^^^^^^^^^^^^^^^^^^^^^^^^^^^^^^^^
  File "C:\Users\user\Desktop\soils-sense\.venv\Lib\site-packages\django\db\models\query.py", line 629, in get
    num = len(clone)
          ^^^^^^^^^^
  File "C:\Users\user\Desktop\soils-sense\.venv\Lib\site-packages\django\db\models\query.py", line 366, in __len__
    self._fetch_all()
  File "C:\Users\user\Desktop\soils-sense\.venv\Lib\site-packages\django\db\models\query.py", line 1949, in _fetch_all
    self._result_cache = list(self._iterable_class(self))
                         ^^^^^^^^^^^^^^^^^^^^^^^^^^^^^^^^
  File "C:\Users\user\Desktop\soils-sense\.venv\Lib\site-packages\django\db\models\query.py", line 91, in __iter__
    results = compiler.execute_sql(
              ^^^^^^^^^^^^^^^^^^^^^
  File "C:\Users\user\Desktop\soils-sense\.venv\Lib\site-packages\django\db\models\sql\compiler.py", line 1623, in execute_sql
    cursor.execute(sql, params)
  File "C:\Users\user\Desktop\soils-sense\.venv\Lib\site-packages\django\db\backends\utils.py", line 122, in execute
    return super().execute(sql, params)
           ^^^^^^^^^^^^^^^^^^^^^^^^^^^^
  File "C:\Users\user\Desktop\soils-sense\.venv\Lib\site-packages\django\db\backends\utils.py", line 79, in execute
    return self._execute_with_wrappers(
           ^^^^^^^^^^^^^^^^^^^^^^^^^^^^
  File "C:\Users\user\Desktop\soils-sense\.venv\Lib\site-packages\django\db\backends\utils.py", line 92, in _execute_with_wrappers
    return executor(sql, params, many, context)
           ^^^^^^^^^^^^^^^^^^^^^^^^^^^^^^^^^^^^
  File "C:\Users\user\Desktop\soils-sense\.venv\Lib\site-packages\django\db\backends\utils.py", line 100, in _execute
    with self.db.wrap_database_errors:
  File "C:\Users\user\Desktop\soils-sense\.venv\Lib\site-packages\django\db\utils.py", line 91, in __exit__
    raise dj_exc_value.with_traceback(traceback) from exc_value
  File "C:\Users\user\Desktop\soils-sense\.venv\Lib\site-packages\django\db\backends\utils.py", line 105, in _execute
    return self.cursor.execute(sql, params)
           ^^^^^^^^^^^^^^^^^^^^^^^^^^^^^^^^
  File "C:\Users\user\Desktop\soils-sense\.venv\Lib\site-packages\django\db\backends\sqlite3\base.py", line 360, in execute
    return super().execute(query, params)
           ^^^^^^^^^^^^^^^^^^^^^^^^^^^^^^
django.db.utils.OperationalError: no such column: authentication_user.reset_code
"GET /authentication/logout/ HTTP/1.1" 500 186972
"GET /administrator/ml-models/ HTTP/1.1" 200 6246
"GET /administrator/ HTTP/1.1" 200 6332
"GET /authentication/signup/ HTTP/1.1" 200 4894
"GET / HTTP/1.1" 200 7339
"GET /static/images/dashboard.png HTTP/1.1" 404 1874
"GET /static/images/chart-preview.png HTTP/1.1" 404 1886
C:\Users\user\Desktop\soils-sense\apps\technician\models.py changed, reloading.
Watching for file changes with StatReloader
"GET /authentication/signup/ HTTP/1.1" 200 5130
"GET /admin/ HTTP/1.1" 302 0
"GET /admin/login/?next=/admin/ HTTP/1.1" 200 3398
"GET /administrator/ HTTP/1.1" 200 6332
"GET /administrator/data/ HTTP/1.1" 200 6436
"GET /administrator/ml-models/ HTTP/1.1" 200 15654
"GET /authentication/logout/ HTTP/1.1" 302 0
"GET /landing_page/ HTTP/1.1" 200 9417
"GET /static/images/dashboard.png HTTP/1.1" 404 1874
"GET /static/images/chart-preview.png HTTP/1.1" 404 1886
"GET /authentication/login/ HTTP/1.1" 200 3838
"GET /authentication/reset/ HTTP/1.1" 200 3254
"GET /authentication/login/ HTTP/1.1" 200 3838
"GET / HTTP/1.1" 200 9417
"GET /static/images/chart-preview.png HTTP/1.1" 404 1886
"GET /static/images/dashboard.png HTTP/1.1" 404 1874
"GET /authentication/signup/ HTTP/1.1" 200 5130
