Watching for file changes with StatReloader
"GET / HTTP/1.1" 200 7339
"GET /static/images/slide1.jpg HTTP/1.1" 304 0
"GET /static/images/chart-preview.png HTTP/1.1" 404 1886
"GET /static/images/dashboard.png HTTP/1.1" 404 1874
Not Found: /favicon.ico
"GET /favicon.ico HTTP/1.1" 404 3929
"GET / HTTP/1.1" 200 7339
"GET /static/images/dashboard.png HTTP/1.1" 404 1874
"GET /static/images/chart-preview.png HTTP/1.1" 404 1886
Watching for file changes with StatReloader
"GET / HTTP/1.1" 200 7339
"GET /static/images/dashboard.png HTTP/1.1" 404 1874
"GET /static/images/chart-preview.png HTTP/1.1" 404 1886
"GET /authentication/signup/ HTTP/1.1" 200 4079
"GET /static/images/logo.webp HTTP/1.1" 304 0
"GET /authentication/signup/ HTTP/1.1" 200 4079
"GET /authentication/login/ HTTP/1.1" 200 2794
"POST /authentication/login/ HTTP/1.1" 302 0
"GET /technician/dashboard/ HTTP/1.1" 200 17175
Forbidden (CSRF token from POST incorrect.): /authentication/login/
"POST /authentication/login/ HTTP/1.1" 403 2503
Forbidden (CSRF token from POST incorrect.): /authentication/login/
"POST /authentication/login/ HTTP/1.1" 403 2503
Forbidden (CSRF token from POST incorrect.): /authentication/login/
"POST /authentication/login/ HTTP/1.1" 403 2503
"GET /authentication/login/ HTTP/1.1" 200 2794
"POST /authentication/login/ HTTP/1.1" 302 0
"GET /farmer/dashboard/ HTTP/1.1" 200 12213
"GET /authentication/logout/ HTTP/1.1" 302 0
"GET /authentication/login/ HTTP/1.1" 200 2794
"POST /authentication/login/ HTTP/1.1" 302 0
"GET /farmer/dashboard/ HTTP/1.1" 200 12213
Internal Server Error: /farmer/farm-management/
Traceback (most recent call last):
  File "C:\Users\user\Desktop\soils-sense\.venv\Lib\site-packages\django\db\backends\utils.py", line 105, in _execute
    return self.cursor.execute(sql, params)
           ^^^^^^^^^^^^^^^^^^^^^^^^^^^^^^^^
  File "C:\Users\user\Desktop\soils-sense\.venv\Lib\site-packages\django\db\backends\sqlite3\base.py", line 360, in execute
    return super().execute(query, params)
           ^^^^^^^^^^^^^^^^^^^^^^^^^^^^^^
sqlite3.OperationalError: no such table: farmer_farm

The above exception was the direct cause of the following exception:

Traceback (most recent call last):
  File "C:\Users\user\Desktop\soils-sense\.venv\Lib\site-packages\django\core\handlers\exception.py", line 55, in inner
    response = get_response(request)
               ^^^^^^^^^^^^^^^^^^^^^
  File "C:\Users\user\Desktop\soils-sense\.venv\Lib\site-packages\django\core\handlers\base.py", line 197, in _get_response
    response = wrapped_callback(request, *callback_args, **callback_kwargs)
               ^^^^^^^^^^^^^^^^^^^^^^^^^^^^^^^^^^^^^^^^^^^^^^^^^^^^^^^^^^^^
  File "C:\Users\user\Desktop\soils-sense\apps\farmer\views.py", line 68, in farm_management
    return render(request, 'farmer/farm_management.html', context)
           ^^^^^^^^^^^^^^^^^^^^^^^^^^^^^^^^^^^^^^^^^^^^^^^^^^^^^^^
  File "C:\Users\user\Desktop\soils-sense\.venv\Lib\site-packages\django\shortcuts.py", line 25, in render
    content = loader.render_to_string(template_name, context, request, using=using)
              ^^^^^^^^^^^^^^^^^^^^^^^^^^^^^^^^^^^^^^^^^^^^^^^^^^^^^^^^^^^^^^^^^^^^^
  File "C:\Users\user\Desktop\soils-sense\.venv\Lib\site-packages\django\template\loader.py", line 62, in render_to_string
    return template.render(context, request)
           ^^^^^^^^^^^^^^^^^^^^^^^^^^^^^^^^^
  File "C:\Users\user\Desktop\soils-sense\.venv\Lib\site-packages\django\template\backends\django.py", line 107, in render
    return self.template.render(context)
           ^^^^^^^^^^^^^^^^^^^^^^^^^^^^^
  File "C:\Users\user\Desktop\soils-sense\.venv\Lib\site-packages\django\template\base.py", line 171, in render
    return self._render(context)
           ^^^^^^^^^^^^^^^^^^^^^
  File "C:\Users\user\Desktop\soils-sense\.venv\Lib\site-packages\django\template\base.py", line 163, in _render
    return self.nodelist.render(context)
           ^^^^^^^^^^^^^^^^^^^^^^^^^^^^^
  File "C:\Users\user\Desktop\soils-sense\.venv\Lib\site-packages\django\template\base.py", line 1016, in render
    return SafeString("".join([node.render_annotated(context) for node in self]))
                               ^^^^^^^^^^^^^^^^^^^^^^^^^^^^^^
  File "C:\Users\user\Desktop\soils-sense\.venv\Lib\site-packages\django\template\base.py", line 977, in render_annotated
    return self.render(context)
           ^^^^^^^^^^^^^^^^^^^^
  File "C:\Users\user\Desktop\soils-sense\.venv\Lib\site-packages\django\template\loader_tags.py", line 159, in render
    return compiled_parent._render(context)
           ^^^^^^^^^^^^^^^^^^^^^^^^^^^^^^^^
  File "C:\Users\user\Desktop\soils-sense\.venv\Lib\site-packages\django\template\base.py", line 163, in _render
    return self.nodelist.render(context)
           ^^^^^^^^^^^^^^^^^^^^^^^^^^^^^
  File "C:\Users\user\Desktop\soils-sense\.venv\Lib\site-packages\django\template\base.py", line 1016, in render
    return SafeString("".join([node.render_annotated(context) for node in self]))
                               ^^^^^^^^^^^^^^^^^^^^^^^^^^^^^^
  File "C:\Users\user\Desktop\soils-sense\.venv\Lib\site-packages\django\template\base.py", line 977, in render_annotated
    return self.render(context)
           ^^^^^^^^^^^^^^^^^^^^
  File "C:\Users\user\Desktop\soils-sense\.venv\Lib\site-packages\django\template\loader_tags.py", line 65, in render
    result = block.nodelist.render(context)
             ^^^^^^^^^^^^^^^^^^^^^^^^^^^^^^
  File "C:\Users\user\Desktop\soils-sense\.venv\Lib\site-packages\django\template\base.py", line 1016, in render
    return SafeString("".join([node.render_annotated(context) for node in self]))
                               ^^^^^^^^^^^^^^^^^^^^^^^^^^^^^^
  File "C:\Users\user\Desktop\soils-sense\.venv\Lib\site-packages\django\template\base.py", line 977, in render_annotated
    return self.render(context)
           ^^^^^^^^^^^^^^^^^^^^
  File "C:\Users\user\Desktop\soils-sense\.venv\Lib\site-packages\django\template\defaulttags.py", line 199, in render
    len_values = len(values)
                 ^^^^^^^^^^^
  File "C:\Users\user\Desktop\soils-sense\.venv\Lib\site-packages\django\db\models\query.py", line 366, in __len__
    self._fetch_all()
  File "C:\Users\user\Desktop\soils-sense\.venv\Lib\site-packages\django\db\models\query.py", line 1949, in _fetch_all
    self._result_cache = list(self._iterable_class(self))
                         ^^^^^^^^^^^^^^^^^^^^^^^^^^^^^^^^
  File "C:\Users\user\Desktop\soils-sense\.venv\Lib\site-packages\django\db\models\query.py", line 91, in __iter__
    results = compiler.execute_sql(
              ^^^^^^^^^^^^^^^^^^^^^
  File "C:\Users\user\Desktop\soils-sense\.venv\Lib\site-packages\django\db\models\sql\compiler.py", line 1623, in execute_sql
    cursor.execute(sql, params)
  File "C:\Users\user\Desktop\soils-sense\.venv\Lib\site-packages\django\db\backends\utils.py", line 122, in execute
    return super().execute(sql, params)
           ^^^^^^^^^^^^^^^^^^^^^^^^^^^^
  File "C:\Users\user\Desktop\soils-sense\.venv\Lib\site-packages\django\db\backends\utils.py", line 79, in execute
    return self._execute_with_wrappers(
           ^^^^^^^^^^^^^^^^^^^^^^^^^^^^
  File "C:\Users\user\Desktop\soils-sense\.venv\Lib\site-packages\django\db\backends\utils.py", line 92, in _execute_with_wrappers
    return executor(sql, params, many, context)
           ^^^^^^^^^^^^^^^^^^^^^^^^^^^^^^^^^^^^
  File "C:\Users\user\Desktop\soils-sense\.venv\Lib\site-packages\django\db\backends\utils.py", line 100, in _execute
    with self.db.wrap_database_errors:
  File "C:\Users\user\Desktop\soils-sense\.venv\Lib\site-packages\django\db\utils.py", line 91, in __exit__
    raise dj_exc_value.with_traceback(traceback) from exc_value
  File "C:\Users\user\Desktop\soils-sense\.venv\Lib\site-packages\django\db\backends\utils.py", line 105, in _execute
    return self.cursor.execute(sql, params)
           ^^^^^^^^^^^^^^^^^^^^^^^^^^^^^^^^
  File "C:\Users\user\Desktop\soils-sense\.venv\Lib\site-packages\django\db\backends\sqlite3\base.py", line 360, in execute
    return super().execute(query, params)
           ^^^^^^^^^^^^^^^^^^^^^^^^^^^^^^
django.db.utils.OperationalError: no such table: farmer_farm
"GET /farmer/farm-management/ HTTP/1.1" 500 212489
C:\Users\user\Desktop\soils-sense\apps\farmer\views.py changed, reloading.
Watching for file changes with StatReloader
C:\Users\user\Desktop\soils-sense\apps\farmer\views.py changed, reloading.
